Workbook
Name UPDATE: 'Data Sheet'!$E$1

Sheet Cover Page 
B1: Tata Steel
H3: Tata Steel Ltd is Asia's first integrated private steel company setup in 1907. The company has presence across the entire value chain of steel manufacturing from mining and processing iron ore and coal to producing and distributing finished products. The company has a target to increase domestic steelmaking capacity to 30 MnTPA by 2025.
B11: Key Company Details | J11: Scope of Work
B13: Chief Operating Officer/Managing Director | F13: Dr.T. V. Narendran | J13: This report presents an equity valuation of Tata Steel Limited to assess its intrinsic value relative to current market pricing. The analysis begins with DuPont Analysis (decomposing Return on Equity into profitability, efficiency, and leverage drivers) and Altman's Z-Score (assessing financial distress risk) to review financial health and earnings quality. A set of operating assumptions, revenue, cost structure, working capital, and capex/depreciation, was then developed to project financials through FY2031, feeding a Discounted Cash Flow valuation. The discount rate uses a bottom-up WACC build with peer beta relevering to a target capital structure, tested across Best/Base/Worst capex scenarios and a WACC-terminal growth sensitivity table. In parallel, Relative Valuation applies EV/EBITDA, EV/Revenue, and EV/EBIT multiples against domestic peers (JSW Steel, SAIL, Jindal Steel & Power, Jindal Stainless). Findings from both approaches are consolidated in a Football Field Analysis, comparing implied valuation ranges against the current market price to support a view on whether Tata Steel is fairly priced, undervalued, or overvalued.
B14: Headquarters | F14: Mumbai, Maharashtra
B15: FY26 Revenue | F15: ₹ 2,32,140 Crores
B16: FY26 EBITDA | F16: ₹ 51,186 Crores
B17: Major Shareholders | F17: Promotors (32.94%)
F18: FIIs (18.9%)
F19: DIIs (26.4%)
F20: Government and Public ( 21.7%)
B30: Key Growth Catalysts
B32: Capacity Expansion: Ongoing expansion projects in India are expected to increase production capacity and support long-term revenue growth.
B33: Infrastructure Demand: Rising government spending on infrastructure and construction is expected to drive domestic steel demand.
B34: Value-Added Products: Increasing focus on high-margin value-added steel products is likely to improve profitability and operating margins.
B35: Operational Efficiency: Continuous cost optimization, digitalization, and efficiency initiatives are expected to enhance margins and cash flow generation.

Sheet Key Financial Metric 
B1: Key Financial Metrics
B3: In (Cr)
B4: Particulars | D4: 45016 | E4: 45382 | F4: 45747 | G4: 46112 | I4: Trend Line | K4: Important Data
B5: Total Sales | D5: ='Forecasted Income Statement '!D5 -> 206922.86 | E5: ='Forecasted Income Statement '!E5 -> 229170.78 | F5: ='Forecasted Income Statement '!F5 -> 218543 | G5: ='Forecasted Income Statement '!G5 -> 232140
B6: Sales Growth (y-o-y) | D6: =D5/'Profit & Loss'!G4-1 -> -0.15181356 | E6: =E5/D5-1 -> 0.10751794 | F6: =F5/E5-1 -> -0.046374935 | G6: =G5/F5-1 -> 0.062216589
B7: EBITDA | D7: ='Forecasted Income Statement '!D10 -> 32383.428 | E7: ='Forecasted Income Statement '!E10 -> 49913.396 | F7: ='Forecasted Income Statement '!F10 -> 47292.705 | G7: ='Forecasted Income Statement '!G10 -> 51186.87
B8: EBITDA Margin (%) | D8: =D7/D5 -> 0.1565 | E8: =E7/E5 -> 0.2178 | F8: =F7/F5 -> 0.2164 | G8: =G7/G5 -> 0.2205
B9: EBIT | D9: ='Forecasted Income Statement '!D12 -> 23048.228 | E9: ='Forecasted Income Statement '!E12 -> 40031.236 | F9: ='Forecasted Income Statement '!F12 -> 36871.375 | G9: ='Forecasted Income Statement '!G12 -> 39232.36
B10: EBIT Margin (%) | D10: =D9/D5 -> 0.1113856 | E10: =E9/E5 -> 0.17467862 | F10: =F9/F5 -> 0.16871451 | G10: =G9/G5 -> 0.16900302
B11: PAT | D11: ='Forecasted Income Statement '!D16 -> 11724.669 | E11: ='Forecasted Income Statement '!E16 -> 22766.566 | F11: ='Forecasted Income Statement '!F16 -> 20671.298 | G11: ='Forecasted Income Statement '!G16 -> 22445.71
B12: Net Margins (%) | D12: =D11/D5 -> 0.05666203 | E12: =E11/E5 -> 0.099343233 | F12: =F11/F5 -> 0.094586867 | G12: =G11/G5 -> 0.096690402
B13: Earnings Per Share | D13: 7.17 | E13: -3.5546441 | F13: 2.7400248 | G13: 8.6465094
B14: EPS Growth (y-o-y) | D14: =D13/'Profit & Loss'!G13-1 -> -0.7819212 | E14: =E13/D13-1 -> -1.4957663 | F14: =F13/E13-1 -> -1.7708296 | G14: =G13/F13-1 -> 2.1556318
B16: Financial Ratios | D16: 45016 | E16: 45382 | F16: 45747 | G16: 46112 | I16: Trend Line
B17: Debt to Equity | D17: ='Ratio Analysis '!D52 -> 0.82354793 | E17: ='Ratio Analysis '!E52 -> 0.94617701 | F17: ='Ratio Analysis '!F52 -> 1.0398315 | G17: ='Ratio Analysis '!G52 -> 0.90421655
B18: Interest Coverage | D18: ='Ratio Analysis '!D53 -> 3.8950609 | E18: ='Ratio Analysis '!E53 -> 0.84721554 | F18: ='Ratio Analysis '!F53 -> 2.1460192 | G18: ='Ratio Analysis '!G53 -> 3.228067
B19: Return on Equity | D19: ='Ratio Analysis '!D22 -> 0.078339013 | E19: ='Ratio Analysis '!E22 -> -0.053344591 | F19: ='Ratio Analysis '!F22 -> 0.034811812 | G19: ='Ratio Analysis '!G22 -> 0.1065486
B20: Return on Capital Employed | D20: ='Ratio Analysis '!D23 -> 0.13051629 | E20: ='Ratio Analysis '!E23 -> 0.035510302 | F20: ='Ratio Analysis '!F23 -> 0.08471131 | G20: ='Ratio Analysis '!G23 -> 0.11891971
B21: Return on Assets | D21: ='Ratio Analysis '!D21 -> 0.028443472 | E21: ='Ratio Analysis '!E21 -> -0.017701595 | F21: ='Ratio Analysis '!F21 -> 0.011651795 | G21: ='Ratio Analysis '!G21 -> 0.038064091
B23: Peer Comparision (Mar 26) | D23: JSW Steel | E23: SAIL | F23: Jindal Steel | G23: Tata Steel | I23: Peer Comparision (Mar 26)
B24: Revenue | D24: 189687 | E24: 110810 | F24: 62412 | G24: =G5 -> 232140
B25: EBITDA Margins | D25: =30712/D24 -> 0.16190883 | E25: =13146/E24 -> 0.1186355 | F25: =9099/F24 -> 0.14578927 | G25: =G8 -> 0.2205
B26: PAT | D26: 12040 | E26: 3233 | F26: 3361 | G26: =G11 -> 22445.71
B27: Net Margins | D27: =D26/D24 -> 0.063472984 | E27: =E26/E24 -> 0.029176067 | F27: =F26/F24 -> 0.053851823 | G27: =G12 -> 0.096690402

Sheet Historical 
B1: Historical Financial Statement - "TATA STEEL"
B4: Income Statement
B5: Particulars | C5: ='[2]Data Sheet'!B56 -> 44286 | D5: ='[2]Data Sheet'!C56 -> 44651 | E5: ='[2]Data Sheet'!D56 -> 45016 | F5: ='[2]Data Sheet'!E56 -> 45382 | G5: ='[2]Data Sheet'!F56 -> 45747 | H5: ='[2]Data Sheet'!G56 -> 46112
B7: Sales | C7: ='[2]Data Sheet'!B17 -> 156477.4 | D7: ='[2]Data Sheet'!C17 -> 243959.17 | E7: ='[2]Data Sheet'!D17 -> 243352.69 | F7: ='[2]Data Sheet'!E17 -> 229170.78 | G7: ='[2]Data Sheet'!F17 -> 218542.51 | H7: ='[2]Data Sheet'!G17 -> 232139.94
B8: COGS | C8: =SUM('[2]Data Sheet'!B18,'[2]Data Sheet'!B20:B22)-1*'[2]Data Sheet'!B19 -> 102979.74 | D8: =SUM('[2]Data Sheet'!C18,'[2]Data Sheet'!C20:C22)-1*'[2]Data Sheet'!C19 -> 143605.19 | E8: =SUM('[2]Data Sheet'!D18,'[2]Data Sheet'!D20:D22)-1*'[2]Data Sheet'!D19 -> 178329.36 | F8: =SUM('[2]Data Sheet'!E18,'[2]Data Sheet'!E20:E22)-1*'[2]Data Sheet'!E19 -> 183154.84 | G8: =SUM('[2]Data Sheet'!F18,'[2]Data Sheet'!F20:F22)-1*'[2]Data Sheet'!F19 -> 171714.99 | H8: =SUM('[2]Data Sheet'!G18,'[2]Data Sheet'!G20:G22)-1*'[2]Data Sheet'!G19 -> 171435.78
B9: Gross Profit | C9: =C7-C8 -> 53497.66 | D9: =D7-D8 -> 100353.98 | E9: =E7-E8 -> 65023.33 | F9: =F7-F8 -> 46015.94 | G9: =G7-G8 -> 46827.52 | H9: =H7-H8 -> 60704.16
B10: Selling & General Expenses | C10: =SUM('[2]Data Sheet'!B23:B24) -> 22993.4 | D10: =SUM('[2]Data Sheet'!C23:C24) -> 36864.03 | E10: =SUM('[2]Data Sheet'!D23:D24) -> 32723.17 | F10: =SUM('[2]Data Sheet'!E23:E24) -> 23768.02 | G10: =SUM('[2]Data Sheet'!F23:F24) -> 21529.07 | H10: =SUM('[2]Data Sheet'!G23:G24) -> 26351.72
B11: EBITDA | C11: =C9-C10 -> 30504.26 | D11: =D9-D10 -> 63489.95 | E11: =E9-E10 -> 32300.16 | F11: =F9-F10 -> 22247.92 | G11: =G9-G10 -> 25298.45 | H11: =H9-H10 -> 34352.44
B12: Interest | C12: ='[2]Data Sheet'!B27 -> 7606.71 | D12: ='[2]Data Sheet'!C27 -> 5462.2 | E12: ='[2]Data Sheet'!D27 -> 6298.7 | F12: ='[2]Data Sheet'!E27 -> 7507.57 | G12: ='[2]Data Sheet'!F27 -> 7340.95 | H12: ='[2]Data Sheet'!G27 -> 7167.06
B13: Depreciation | C13: ='[2]Data Sheet'!B26 -> 9233.64 | D13: ='[2]Data Sheet'!C26 -> 9100.87 | E13: ='[2]Data Sheet'!D26 -> 9335.2 | F13: ='[2]Data Sheet'!E26 -> 9882.16 | G13: ='[2]Data Sheet'!F26 -> 10421.33 | H13: ='[2]Data Sheet'!G26 -> 11954.51
B14: Other Income | C14: ='[2]Data Sheet'!B25 -> 179.78 | D14: ='[2]Data Sheet'!C25 -> 1299.99 | E14: ='[2]Data Sheet'!D25 -> 1568.86 | F14: ='[2]Data Sheet'!E25 -> -6005.23 | G14: ='[2]Data Sheet'!F25 -> 876.7 | H14: ='[2]Data Sheet'!G25 -> 737.82
B15: Earnings Before Tax | C15: =IFERROR(C11-SUM(C13,C12,-C14),0) -> 13843.69 | D15: =IFERROR(D11-SUM(D13,D12,-D14),0) -> 50226.87 | E15: =IFERROR(E11-SUM(E13,E12,-E14),0) -> 18235.12 | F15: =IFERROR(F11-SUM(F13,F12,-F14),0) -> -1147.04 | G15: =IFERROR(G11-SUM(G13,G12,-G14),0) -> 8412.87 | H15: =IFERROR(H11-SUM(H13,H12,-H14),0) -> 15968.69
B16: Tax | C16: ='[2]Data Sheet'!B29 -> 5653.9 | D16: ='[2]Data Sheet'!C29 -> 8477.55 | E16: ='[2]Data Sheet'!D29 -> 10159.77 | F16: ='[2]Data Sheet'!E29 -> 3762.57 | G16: ='[2]Data Sheet'!F29 -> 5239.09 | H16: ='[2]Data Sheet'!G29 -> 5082.87
B17: Net Profit | C17: =IFERROR(C15-C16,0) -> 8189.79 | D17: =IFERROR(D15-D16,0) -> 41749.32 | E17: =IFERROR(E15-E16,0) -> 8075.35 | F17: =IFERROR(F15-F16,0) -> -4909.61 | G17: =IFERROR(G15-G16,0) -> 3173.78 | H17: =IFERROR(H15-H16,0) -> 10885.82
B18: No of Equity Shares | C18: ='[2]Data Sheet'!B127 -> 1196.59 | D18: ='[2]Data Sheet'!C127 -> 1221.3 | E18: ='[2]Data Sheet'!D127 -> 1222.15 | F18: ='[2]Data Sheet'!E127 -> 1248.35 | G18: ='[2]Data Sheet'!F127 -> 1248.35 | H18: ='[2]Data Sheet'!G127 -> 1248.35
B19: Earnings per Share | C19: =IFERROR(C17/C18,0) -> 6.8442741 | D19: =IFERROR(D17/D18,0) -> 34.184328 | E19: =IFERROR(E17/E18,0) -> 6.607495 | F19: =IFERROR(F17/F18,0) -> -3.9328794 | G19: =IFERROR(G17/G18,0) -> 2.5423799 | H19: =IFERROR(H17/H18,0) -> 8.7201666
B20: Dividend per Share | C20: ='[2]Data Sheet'!B31/[2]HistoricalFS!C39 -> 2.5021269 | D20: ='[2]Data Sheet'!C31/[2]HistoricalFS!D39 -> 5.0996234 | E20: ='[2]Data Sheet'!D31/[2]HistoricalFS!E39 -> 3.5973162 | F20: ='[2]Data Sheet'!E31/[2]HistoricalFS!F39 -> 3.5973725 | G20: ='[2]Data Sheet'!F31/[2]HistoricalFS!G39 -> 3.5973725 | H20: ='[2]Data Sheet'!G31/[2]HistoricalFS!H39 -> 3.9970842
B21: Dividend payout ratio | C21: =IFERROR(C20/C19,0) -> 0.36557958 | D21: =IFERROR(D20/D19,0) -> 0.14918015 | E21: =IFERROR(E20/E19,0) -> 0.54442965 | F21: =IFERROR(F20/F19,0) -> -0.9146918 | G21: =IFERROR(G20/G19,0) -> 1.4149626 | H21: =IFERROR(H20/H19,0) -> 0.45837245
B22: Retained Earnings | C22: =IFERROR(IF(C19>C20,1-C21,0),0) -> 0.63442042 | D22: =IFERROR(IF(D19>D20,1-D21,0),0) -> 0.85081985 | E22: =IFERROR(IF(E19>E20,1-E21,0),0) -> 0.45557035 | F22: =IFERROR(IF(F19>F20,1-F21,0),0) -> 0 | G22: =IFERROR(IF(G19>G20,1-G21,0),0) -> 0 | H22: =IFERROR(IF(H19>H20,1-H21,0),0) -> 0.54162755
B24: Balance Sheet
A25: # | B25: Particulars | C25: 44256 | D25: 44651 | E25: 45016 | F25: 45382 | G25: 45747 | H25: 46112
B27: Equity Share Capital | C27: ='[2]Data Sheet'!B57 -> 1197.61 | D27: ='[2]Data Sheet'!C57 -> 1221.21 | E27: ='[2]Data Sheet'!D57 -> 1221.24 | F27: ='[2]Data Sheet'!E57 -> 1247.44 | G27: ='[2]Data Sheet'!F57 -> 1247.44 | H27: ='[2]Data Sheet'!G57 -> 1247.44
B28: Reserves | C28: ='[2]Data Sheet'!B58 -> 73041.16 | D28: ='[2]Data Sheet'!C58 -> 113221.83 | E28: ='[2]Data Sheet'!D58 -> 101860.86 | F28: ='[2]Data Sheet'!E58 -> 90788.32 | G28: ='[2]Data Sheet'!F58 -> 89922.19 | H28: ='[2]Data Sheet'!G58 -> 100920.21
B29: Borrowings | C29: ='[2]Data Sheet'!B59 -> 88501.41 | D29: ='[2]Data Sheet'!C59 -> 75561.35 | E29: ='[2]Data Sheet'!D59 -> 84893.05 | F29: ='[2]Data Sheet'!E59 -> 87082.12 | G29: ='[2]Data Sheet'!F59 -> 94801.05 | H29: ='[2]Data Sheet'!G59 -> 92381.68
B30: Other Liabilities | C30: ='[2]Data Sheet'!B60-SUM('[2]Data Sheet'!B62:B63) -> 52803.01 | D30: ='[2]Data Sheet'!C60-SUM('[2]Data Sheet'!C62:C63) -> 52399.28 | E30: ='[2]Data Sheet'!D60-SUM('[2]Data Sheet'!D62:D63) -> 56193.63 | F30: ='[2]Data Sheet'!E60-SUM('[2]Data Sheet'!E62:E63) -> 57195.54 | G30: ='[2]Data Sheet'!F60-SUM('[2]Data Sheet'!F62:F63) -> 58518.9 | H30: ='[2]Data Sheet'!G60-SUM('[2]Data Sheet'!G62:G63) -> 64933.29
B31: Trade Payables | C31: ='[2]Data Sheet'!B62 -> 25967 | D31: ='[2]Data Sheet'!C62 -> 36765 | E31: ='[2]Data Sheet'!D62 -> 37833 | F31: ='[2]Data Sheet'!E62 -> 30228 | G31: ='[2]Data Sheet'!F62 -> 29314 | H31: ='[2]Data Sheet'!G62 -> 34810
B32: Advance from Customers | C32: ='[2]Data Sheet'!B63 -> 2399 | D32: ='[2]Data Sheet'!C63 -> 3253 | E32: ='[2]Data Sheet'!D63 -> 3394 | F32: ='[2]Data Sheet'!E63 -> 2771 | G32: ='[2]Data Sheet'!F63 -> 1655 | H32: ='[2]Data Sheet'!G63 -> 2222
B33: Total Liabilities | C33: =SUM(C27:C32) -> 243909.19 | D33: =SUM(D27:D32) -> 282421.67 | E33: =SUM(E27:E32) -> 285395.78 | F33: =SUM(F27:F32) -> 269312.42 | G33: =SUM(G27:G32) -> 275458.58 | H33: =SUM(H27:H32) -> 296514.62
B35: Fixed Assets Net Block | C35: ='[2]Data Sheet'!B66 -> 135775.18 | D35: ='[2]Data Sheet'!C66 -> 133287.83 | E35: ='[2]Data Sheet'!D66 -> 146621.46 | F35: ='[2]Data Sheet'!E66 -> 148814.38 | G35: ='[2]Data Sheet'!F66 -> 150914.06 | H35: ='[2]Data Sheet'!G66 -> 179908.13
B36: Capital Work in Progress | C36: ='[2]Data Sheet'!B67 -> 19007.4 | D36: ='[2]Data Sheet'!C67 -> 22045.55 | E36: ='[2]Data Sheet'!D67 -> 31213.02 | F36: ='[2]Data Sheet'!E67 -> 34355.53 | G36: ='[2]Data Sheet'!F67 -> 41622.35 | H36: ='[2]Data Sheet'!G67 -> 28496.71
B37: Investments | C37: ='[2]Data Sheet'!B68 -> 10681.93 | D37: ='[2]Data Sheet'!C68 -> 13139.85 | E37: ='[2]Data Sheet'!D68 -> 8410.31 | F37: ='[2]Data Sheet'!E68 -> 6257.57 | G37: ='[2]Data Sheet'!F68 -> 6194.11 | H37: ='[2]Data Sheet'!G68 -> 7088.85
B38: Other Assets | C38: ='[2]Data Sheet'!B69-SUM('[2]Data Sheet'!B70:B72) -> 29846.28 | D38: ='[2]Data Sheet'!C69-SUM('[2]Data Sheet'!C70:C72) -> 36978.69 | E38: ='[2]Data Sheet'!D69-SUM('[2]Data Sheet'!D70:D72) -> 23121.16 | F38: ='[2]Data Sheet'!E69-SUM('[2]Data Sheet'!E70:E72) -> 15786.18 | G38: ='[2]Data Sheet'!F69-SUM('[2]Data Sheet'!F70:F72) -> 15231.08 | H38: ='[2]Data Sheet'!G69-SUM('[2]Data Sheet'!G70:G72) -> 18797.29
B39: Total Non Current Assets | C39: =SUM(C35:C38) -> 195310.79 | D39: =SUM(D35:D38) -> 205451.92 | E39: =SUM(E35:E38) -> 209365.95 | F39: =SUM(F35:F38) -> 205213.66 | G39: =SUM(G35:G38) -> 213961.6 | H39: =SUM(H35:H38) -> 234290.98
B41: Receivables | C41: ='[2]Data Sheet'!B70 -> 9539.84 | D41: ='[2]Data Sheet'!C70 -> 12246.43 | E41: ='[2]Data Sheet'!D70 -> 8257.24 | F41: ='[2]Data Sheet'!E70 -> 6263.53 | G41: ='[2]Data Sheet'!F70 -> 5260.06 | H41: ='[2]Data Sheet'!G70 -> 4916.89
B42: Inventory | C42: ='[2]Data Sheet'!B71 -> 33276.38 | D42: ='[2]Data Sheet'!C71 -> 48824.39 | E42: ='[2]Data Sheet'!D71 -> 54415.33 | F42: ='[2]Data Sheet'!E71 -> 49157.51 | G42: ='[2]Data Sheet'!F71 -> 44589.94 | H42: ='[2]Data Sheet'!G71 -> 47249.22
B43: Cash & Bank | C43: ='[2]Data Sheet'!B72 -> 5782.18 | D43: ='[2]Data Sheet'!C72 -> 15898.93 | E43: ='[2]Data Sheet'!D72 -> 13357.26 | F43: ='[2]Data Sheet'!E72 -> 8677.72 | G43: ='[2]Data Sheet'!F72 -> 11646.98 | H43: ='[2]Data Sheet'!G72 -> 10057.53
B44: Total Current Assets | C44: =IFERROR(SUM(C41:C43),0) -> 48598.4 | D44: =IFERROR(SUM(D41:D43),0) -> 76969.75 | E44: =IFERROR(SUM(E41:E43),0) -> 76029.83 | F44: =IFERROR(SUM(F41:F43),0) -> 64098.76 | G44: =IFERROR(SUM(G41:G43),0) -> 61496.98 | H44: =IFERROR(SUM(H41:H43),0) -> 62223.64
B46: Total Assets | C46: =IFERROR(C44+C39,0) -> 243909.19 | D46: =IFERROR(D44+D39,0) -> 282421.67 | E46: =IFERROR(E44+E39,0) -> 285395.78 | F46: =IFERROR(F44+F39,0) -> 269312.42 | G46: =IFERROR(G44+G39,0) -> 275458.58 | H46: =IFERROR(H44+H39,0) -> 296514.62
A48: # | B48: Check | C48: =ROUND(C33,0)=ROUND(C46,0) -> TRUE | D48: =ROUND(D33,0)=ROUND(D46,0) -> TRUE | E48: =ROUND(E33,0)=ROUND(E46,0) -> TRUE | F48: =ROUND(F33,0)=ROUND(F46,0) -> TRUE | G48: =ROUND(G33,0)=ROUND(G46,0) -> TRUE | H48: =ROUND(H33,0)=ROUND(H46,0) -> TRUE
A50: # | B50: Cash Flow
...

Sheet Ratio Analysis 
B1: Ratio Analysis
B4: Liquidity Ratio
C6: FY22 | D6: FY23 | E6: FY24 | F6: FY25 | G6: FY26
B7: Current Ratio | C7: ='Historical '!D44/('Historical '!D30+'Historical '!D31+'Historical '!D32) -> 0.8328502 | D7: ='Historical '!E44/('Historical '!E30+'Historical '!E31+'Historical '!E32) -> 0.78042844 | E7: ='Historical '!F44/('Historical '!F30+'Historical '!F31+'Historical '!F32) -> 0.71067229 | F7: ='Historical '!G44/('Historical '!G30+'Historical '!G31+'Historical '!G32) -> 0.68721 | G7: ='Historical '!H44/('Historical '!H30+'Historical '!H31+'Historical '!H32) -> 0.61024335
B8: Quick Ratio | C8: =('Historical '!D41+'Historical '!D43)/('Historical '!D30+'Historical '!D31+'Historical '!D32) -> 0.30454651 | D8: =('Historical '!E41+'Historical '!E43)/('Historical '!E30+'Historical '!E31+'Historical '!E32) -> 0.22186779 | E8: =('Historical '!F41+'Historical '!F43)/('Historical '!F30+'Historical '!F31+'Historical '!F32) -> 0.16565581 | F8: =('Historical '!G41+'Historical '!G43)/('Historical '!G30+'Historical '!G31+'Historical '!G32) -> 0.18893102 | G8: =('Historical '!H41+'Historical '!H43)/('Historical '!H30+'Historical '!H31+'Historical '!H32) -> 0.14685801
B11: Interpretation
B12: Current Ratio: The current ratio declined from 0.83x to 0.61x, indicating weakening short-term liquidity.
B13: Quick Ratio: The quick ratioFell from 0.30x to 0.15x, showing limited ability to meet short-term obligations without relying on inventory.
B15: Profitability Ratio
C17: FY22 | D17: FY23 | E17: FY24 | F17: FY25 | G17: FY26
B18: Gross Profit Margin | C18: ='Historical '!D9/'Historical '!D7 -> 0.41135564 | D18: ='Historical '!E9/'Historical '!E7 -> 0.26719791 | E18: ='Historical '!F9/'Historical '!F7 -> 0.20079323 | F18: ='Historical '!G9/'Historical '!G7 -> 0.21427191 | G18: ='Historical '!H9/'Historical '!H7 -> 0.26149813
B19: Operating Profit Margin | C19: ='Historical '!D11/'Historical '!D7 -> 0.26024826 | D19: ='Historical '!E11/'Historical '!E7 -> 0.13272983 | E19: ='Historical '!F11/'Historical '!F7 -> 0.09708009 | F19: ='Historical '!G11/'Historical '!G7 -> 0.11575986 | G19: ='Historical '!H11/'Historical '!H7 -> 0.1479816
B20: Net Profit Margin | C20: ='Historical '!D17/'Historical '!D7 -> 0.17113241 | D20: ='Historical '!E17/'Historical '!E7 -> 0.03318373 | E20: ='Historical '!F17/'Historical '!F7 -> -0.021423368 | F20: ='Historical '!G17/'Historical '!G7 -> 0.014522484 | G20: ='Historical '!H17/'Historical '!H7 -> 0.046893352
B21: Return on Assets | C21: ='Historical '!D17/(('Historical '!C46+'Historical '!D46)/2) -> 0.15864287 | D21: ='Historical '!E17/(('Historical '!D46+'Historical '!E46)/2) -> 0.028443472 | E21: ='Historical '!F17/(('Historical '!E46+'Historical '!F46)/2) -> -0.017701595 | F21: ='Historical '!G17/(('Historical '!F46+'Historical '!G46)/2) -> 0.011651795 | G21: ='Historical '!H17/(('Historical '!G46+'Historical '!H46)/2) -> 0.038064091
B22: Return on Equity | C22: ='Historical '!D17/('Historical '!D27+'Historical '!D28) -> 0.36480436 | D22: ='Historical '!E17/('Historical '!E27+'Historical '!E28) -> 0.078339013 | E22: ='Historical '!F17/('Historical '!F27+'Historical '!F28) -> -0.053344591 | F22: ='Historical '!G17/('Historical '!G27+'Historical '!G28) -> 0.034811812 | G22: ='Historical '!H17/('Historical '!H27+'Historical '!H28) -> 0.1065486
B23: Return on Capital Employed | C23: =('Historical '!D15+'Historical '!D12)/('Historical '!D46-'Historical '!D30-'Historical '!D31-'Historical '!D32) -> 0.2930936 | D23: =('Historical '!E15+'Historical '!E12)/('Historical '!E46-'Historical '!E30-'Historical '!E31-'Historical '!E32) -> 0.13051629 | E23: =('Historical '!F15+'Historical '!F12)/('Historical '!F46-'Historical '!F30-'Historical '!F31-'Historical '!F32) -> 0.035510302 | F23: =('Historical '!G15+'Historical '!G12)/('Historical '!G46-'Historical '!G30-'Historical '!G31-'Historical '!G32) -> 0.08471131 | G23: =('Historical '!H15+'Historical '!H12)/('Historical '!H46-'Historical '!H30-'Historical '!H31-'Historical '!H32) -> 0.11891971
B26: Interpretation
B27: Gross Profit Margin: Gross margin improved to 15% in FY26, indicating better control over production costs and stronger pricing.
B28: Operating Profit Margin: Operating margin recovered steadily after FY24, reflecting improved operating efficiency and cost management.
B29: Net Profit Margin: Net margin turned positive after FY24 and increased to 5% in FY26, indicating improved overall profitability.
B30: Return on Assets (ROA): ROA improved consistently after FY24, reflecting better utilization of the company's asset base.
B31: Return on Equity (ROE): ROE recovered from a negative return in FY24 to 11% in FY26, indicating improved returns for shareholders.
B32: Return on Capital Employed (ROCE): ROCE improved over the period, demonstrating more efficient utilization of long-term capital.
B34: Efficiency Ratio
C36: FY22 | D36: FY23 | E36: FY24 | F36: FY25 | G36: FY26
B37: Inventory Turnover | C37: =[3]HistoricalFS!D9/AVERAGE([3]HistoricalFS!C65:D65) -> 3.4982666 | D37: =[3]HistoricalFS!E9/AVERAGE([3]HistoricalFS!D65:E65) -> 3.4546657 | E37: =[3]HistoricalFS!F9/AVERAGE([3]HistoricalFS!E65:F65) -> 3.5367349 | F37: =[3]HistoricalFS!G9/AVERAGE([3]HistoricalFS!F65:G65) -> 3.6633528 | G37: =[3]HistoricalFS!H9/AVERAGE([3]HistoricalFS!G65:H65) -> 3.7333917
B38: Debtors Turnover | C38: =[3]HistoricalFS!D6/AVERAGE([3]HistoricalFS!C64:D64) -> 22.39568 | D38: =[3]HistoricalFS!E6/AVERAGE([3]HistoricalFS!D64:E64) -> 23.737476 | E38: =[3]HistoricalFS!F6/AVERAGE([3]HistoricalFS!E64:F64) -> 31.564549 | F38: =[3]HistoricalFS!G6/AVERAGE([3]HistoricalFS!F64:G64) -> 37.929588 | G38: =[3]HistoricalFS!H6/AVERAGE([3]HistoricalFS!G64:H64) -> 45.620729
B39: Asset Turnover | C39: =[3]HistoricalFS!D6/[3]HistoricalFS!D69 -> 0.8638118 | D39: =[3]HistoricalFS!E6/[3]HistoricalFS!E69 -> 0.85268496 | E39: =[3]HistoricalFS!F6/[3]HistoricalFS!F69 -> 0.85094768 | F39: =[3]HistoricalFS!G6/[3]HistoricalFS!G69 -> 0.79337703 | G39: =[3]HistoricalFS!H6/[3]HistoricalFS!H69 -> 0.78289543
B40: Working Capital Turnover | C40: =[3]HistoricalFS!D6/([3]HistoricalFS!D67-SUM([3]HistoricalFS!D54:D55)) -> 6.6021006 | D40: =[3]HistoricalFS!E6/([3]HistoricalFS!E67-SUM([3]HistoricalFS!E54:E55)) -> 6.9923248 | E40: =[3]HistoricalFS!F6/([3]HistoricalFS!F67-SUM([3]HistoricalFS!F54:F55)) -> 7.3688922 | F40: =[3]HistoricalFS!G6/([3]HistoricalFS!G67-SUM([3]HistoricalFS!G54:G55)) -> 7.1587609 | G40: =[3]HistoricalFS!H6/([3]HistoricalFS!H67-SUM([3]HistoricalFS!H54:H55)) -> 9.2149594
B43: Interpretation
B44: Inventory Turnover: Inventory turnover remained around 3x, indicating efficient inventory management and steady inventory movement.
B45: Debtors Turnover: Debtors turnover remained stable, reflecting consistent collection efficiency and effective receivables management.
B46: Asset Turnover: Asset turnover improved gradually from 0.53x to 0.64x, indicating better utilization of assets to generate revenue.
B47: Working Capital Turnover: Working capital turnover increased to 13.38x in FY26, reflecting improved efficiency in utilizing working capital to drive sales.
B49: Solvency Ratio
C51: FY22 | D51: FY23 | E51: FY24 | F51: FY25 | G51: FY26
B52: Debt Equity Ratio | C52: ='Historical '!D29/('Historical '!D27+'Historical '!D28) -> 0.66025291 | D52: ='Historical '!E29/('Historical '!E27+'Historical '!E28) -> 0.82354793 | E52: ='Historical '!F29/('Historical '!F27+'Historical '!F28) -> 0.94617701 | F52: ='Historical '!G29/('Historical '!G27+'Historical '!G28) -> 1.0398315 | G52: ='Historical '!H29/('Historical '!H27+'Historical '!H28) -> 0.90421655
B53: Interest Coverage Ratio | C53: =('Historical '!D15+'Historical '!D12)/'Historical '!D12 -> 10.195355 | D53: =('Historical '!E15+'Historical '!E12)/'Historical '!E12 -> 3.8950609 | E53: =('Historical '!F15+'Historical '!F12)/'Historical '!F12 -> 0.84721554 | F53: =('Historical '!G15+'Historical '!G12)/'Historical '!G12 -> 2.1460192 | G53: =('Historical '!H15+'Historical '!H12)/'Historical '!H12 -> 3.228067
B57: Interpretation
B58: Debt Equity Ratio: The debt-equity ratio remained below 1x throughout the period, indicating a balanced capital structure and prudent use of leverage.
...

Sheet Beneish -M Score 
B1: Beneish M Score
B4: Historical Input | F4: FY25 | G4: FY26
B6: Revenue | F6: ='Historical '!G7 -> 218542.51 | G6: ='Historical '!H7 -> 232139.94
B7: Trade Receivables | F7: ='Historical '!G41 -> 5260.06 | G7: ='Historical '!H41 -> 4916.89
B8: COGS | F8: ='Historical '!G8 -> 171714.99 | G8: ='Historical '!H8 -> 171435.78
B9: Current Assets | F9: ='Historical '!G44 -> 61496.98 | G9: ='Historical '!H44 -> 62223.64
B10: Net PP&E | F10: ='Historical '!G35 -> 150914.06 | G10: ='Historical '!H35 -> 179908.13
B11: Total Assets | F11: ='Historical '!G46 -> 275458.58 | G11: ='Historical '!H46 -> 296514.62
B12: Depreciation | F12: ='Historical '!G13 -> 10421.33 | G12: ='Historical '!H13 -> 11954.51
B13: SG&A | F13: ='Historical '!G10 -> 21529.07 | G13: ='Historical '!H10 -> 26351.72
B14: Total Debt | F14: ='Historical '!G29 -> 94801.05 | G14: ='Historical '!H29 -> 92381.68
B15: PAT | F15: ='Historical '!G17 -> 3173.78 | G15: ='Historical '!H17 -> 10885.82
B16: Cash Flow from Operations | F16: ='Historical '!G62 -> 23138 | G16: ='Historical '!H62 -> 35064
B18: Beneish Score | G18: Score
B20: Days' Sales in Receivables Index | G20: =(G7/G6)/(F7/F6) -> 0.88000645
B21: Gross Margin Index | G21: =((F6-F8)/F6)/((G6-G8)/G6) -> 0.81940129
B22: Asset Quality Index | G22: =(1-((G9+G10)/G11))/(1-((F9+F10)/F11)) -> 0.80131636
B23: Sales Growth Index | G23: =G6/F6 -> 1.0622187
B24: Depreciation Index | G24: =(F12/(F12+F10))/(G12/(G10+G12)) -> 1.0366977
B25: Selling, General & Administrative Index | G25: =(G13/G6)/(F13/F6) -> 1.1523111
B26: Leverage Index | G26: =(G14/G11)/(F14/F11) -> 0.90527995
B27: Total Accruals to Total Assets | G27: =(G15-G16)/G11 -> -0.081541274
B29: Variable | F29: Weight
B31: Constant | G31: −4.84
B32: DSRI | G32: 0.92
B33: GMI | G33: 0.528
B34: AQI | G34: 0.404
B35: SGI | G35: 0.892
B36: DEPI | G36: 0.115
B37: SGAI | G37: −0.172
B38: TATA | G38: 4.679
B39: LVGI | G39: −0.327
B41: M score | F41: =-4.84+0.92*0.88+0.82*0.53+0.4*0.8+0.89*1.06+1.04*0.12+1.15*-0.172+4.68*-0.08+0.91*-0.327 -> -3.07737

Sheet Comparative Income Statement 
B1: Comparative Statement
B4: Income Statement
B5: (In Cr)
B6: Particulars | D6: 44256 | E6: ='Profit & Loss'!G3 -> 44651 | F6: ='Profit & Loss'!H3 -> 45016 | G6: ='Profit & Loss'!I3 -> 45382 | H6: ='Profit & Loss'!J3 -> 45747 | I6: ='Profit & Loss'!K3 -> 46112 | K6: Trend Analysis
B8: ='Profit & Loss'!A4 -> Sales | D8: ='Historical '!C7 -> 156477.4 | E8: ='Historical '!D7 -> 243959.17 | F8: ='Historical '!E7 -> 243352.69 | G8: ='Historical '!F7 -> 229170.78 | H8: ='Historical '!G7 -> 218542.51 | I8: ='Historical '!H7 -> 232139.94
B9: y-o-y growth | D9: 0 | E9: =E8/D8-1 -> 0.55906968 | F9: =F8/E8-1 -> -0.0024859898 | G9: =G8/F8-1 -> -0.058277186 | H9: =H8/G8-1 -> -0.046377073 | I9: =I8/H8-1 -> 0.062218696
B11: Cost of Goods Sold | D11: ='Historical '!C8 -> 102979.74 | E11: ='Historical '!D8 -> 143605.19 | F11: ='Historical '!E8 -> 178329.36 | G11: ='Historical '!F8 -> 183154.84 | H11: ='Historical '!G8 -> 171714.99 | I11: ='Historical '!H8 -> 171435.78
B12: y-o-y growth | D12: 0 | E12: =E11/D11-1 -> 0.39449944 | F12: =F11/E11-1 -> 0.24180303 | G12: =G11/F11-1 -> 0.027059369 | H12: =H11/G11-1 -> -0.062459993 | I12: =I11/H11-1 -> -0.0016260083
B14: Gross Profit | D14: ='Historical '!C9 -> 53497.66 | E14: ='Historical '!D9 -> 100353.98 | F14: ='Historical '!E9 -> 65023.33 | G14: ='Historical '!F9 -> 46015.94 | H14: ='Historical '!G9 -> 46827.52 | I14: ='Historical '!H9 -> 60704.16
B15: y-o-y growth | D15: 0 | E15: =E14/D14-1 -> 0.87585737 | F15: =F14/E14-1 -> -0.35206028 | G15: =G14/F14-1 -> -0.29231647 | H15: =H14/G14-1 -> 0.017636932 | I15: =I14/H14-1 -> 0.29633515
B17: Selling & General Expenses | D17: ='Historical '!C10 -> 22993.4 | E17: ='Historical '!D10 -> 36864.03 | F17: ='Historical '!E10 -> 32723.17 | G17: ='Historical '!F10 -> 23768.02 | H17: ='Historical '!G10 -> 21529.07 | I17: ='Historical '!H10 -> 26351.72
B18: y-o-y growth | D18: 0 | E18: =E17/D17-1 -> 0.60324397 | F18: =F17/E17-1 -> -0.11232793 | G18: =G17/F17-1 -> -0.27366389 | H18: =H17/G17-1 -> -0.094200106 | I18: =I17/H17-1 -> 0.22400642
B20: EBITDA | D20: ='Historical '!C11 -> 30504.26 | E20: ='Historical '!D11 -> 63489.95 | F20: ='Historical '!E11 -> 32300.16 | G20: ='Historical '!F11 -> 22247.92 | H20: ='Historical '!G11 -> 25298.45 | I20: ='Historical '!H11 -> 34352.44
B21: y-o-y growth | D21: 0 | E21: =E20/D20-1 -> 1.081347 | F21: =F20/E20-1 -> -0.49125555 | G21: =G20/F20-1 -> -0.31121332 | H21: =H20/G20-1 -> 0.13711529 | I21: =I20/H20-1 -> 0.35788714
B23: Interest | D23: ='Historical '!C12 -> 7606.71 | E23: ='Profit & Loss'!G9 -> 5462.2 | F23: ='Profit & Loss'!H9 -> 6298.7 | G23: ='Profit & Loss'!I9 -> 7507.57 | H23: ='Profit & Loss'!J9 -> 7340.95 | I23: ='Profit & Loss'!K9 -> 7167.06
B24: y-o-y growth | D24: 0 | E24: =E23/D23-1 -> -0.28192346 | F24: =F23/E23-1 -> 0.15314342 | G24: =G23/F23-1 -> 0.19192373 | H24: =H23/G23-1 -> -0.022193599 | I24: =I23/H23-1 -> -0.02368767
B26: Depreciation | D26: ='Historical '!C13 -> 9233.64 | E26: ='Historical '!D13 -> 9100.87 | F26: ='Historical '!E13 -> 9335.2 | G26: ='Historical '!F13 -> 9882.16 | H26: ='Historical '!G13 -> 10421.33 | I26: ='Historical '!H13 -> 11954.51
B27: y-o-y growth | D27: 0 | E27: =E26/D26-1 -> -0.014378945 | F27: =F26/E26-1 -> 0.025748088 | G27: =G26/F26-1 -> 0.058591139 | H27: =H26/G26-1 -> 0.054559934 | I27: =I26/H26-1 -> 0.14711942
B29: Other Income | D29: ='Historical '!C14 -> 179.78 | E29: ='Historical '!D14 -> 1299.99 | F29: ='Historical '!E14 -> 1568.86 | G29: ='Historical '!F14 -> -6005.23 | H29: ='Historical '!G14 -> 876.7 | I29: ='Historical '!H14 -> 737.82
B30: y-o-y growth | D30: 0 | E30: =E29/D29-1 -> 6.2310046 | F30: =F29/E29-1 -> 0.20682467 | G30: =G29/F29-1 -> -4.8277667 | H30: =H29/G29-1 -> -1.1459894 | I30: =I29/H29-1 -> -0.15841223
B32: Earnings Before Tax | D32: ='Historical '!C15 -> 13843.69 | E32: ='Historical '!D15 -> 50226.87 | F32: ='Historical '!E15 -> 18235.12 | G32: ='Historical '!F15 -> -1147.04 | H32: ='Historical '!G15 -> 8412.87 | I32: ='Historical '!H15 -> 15968.69
B33: y-o-y growth | D33: 0 | E33: =E32/D32-1 -> 2.6281418 | F33: =F32/E32-1 -> -0.63694493 | G33: =G32/F32-1 -> -1.0629028 | H33: =H32/G32-1 -> -8.3344173 | I33: =I32/H32-1 -> 0.89812632
B35: Tax | D35: ='Historical '!C16 -> 5653.9 | E35: ='Historical '!D16 -> 8477.55 | F35: ='Historical '!E16 -> 10159.77 | G35: ='Historical '!F16 -> 3762.57 | H35: ='Historical '!G16 -> 5239.09 | I35: ='Historical '!H16 -> 5082.87
B36: y-o-y growth | D36: 0 | E36: =E35/D35-1 -> 0.49941633 | F36: =F35/E35-1 -> 0.19843233 | G36: =G35/F35-1 -> -0.62965992 | H36: =H35/G35-1 -> 0.39242326 | I36: =I35/H35-1 -> -0.029818155
B38: Net Profit | D38: ='Historical '!C17 -> 8189.79 | E38: ='Historical '!D17 -> 41749.32 | F38: ='Historical '!E17 -> 8075.35 | G38: ='Historical '!F17 -> -4909.61 | H38: ='Historical '!G17 -> 3173.78 | I38: ='Historical '!H17 -> 10885.82
B39: y-o-y growth | D39: 0 | E39: =E38/D38-1 -> 4.0977278 | F39: =F38/E38-1 -> -0.80657529 | G39: =G38/F38-1 -> -1.6079749 | H39: =H38/G38-1 -> -1.6464424 | I39: =I38/H38-1 -> 2.4299227

Sheet Comparative Balance Sheet  
B1: Comparative Statement
B4: Balance Sheet
B5: (In Cr)
B6: Particulars | D6: 44256 | E6: ='Profit & Loss'!G3 -> 44651 | F6: ='Profit & Loss'!H3 -> 45016 | G6: ='Profit & Loss'!I3 -> 45382 | H6: ='Profit & Loss'!J3 -> 45747 | I6: ='Profit & Loss'!K3 -> 46112 | K6: Trend Analysis
B8: ='Balance Sheet'!A4 -> Equity Share Capital | D8: ='Historical '!C27 -> 1197.61 | E8: ='Historical '!D27 -> 1221.21 | F8: ='Historical '!E27 -> 1221.24 | G8: ='Historical '!F27 -> 1247.44 | H8: ='Historical '!G27 -> 1247.44 | I8: ='Historical '!H27 -> 1247.44
B9: y-o-y growth | D9: 0 | E9: =E8/D8-1 -> 0.019705914 | F9: =F8/E8-1 -> 2.4565799e-05 | G9: =G8/F8-1 -> 0.021453605 | H9: =H8/G8-1 -> 0 | I9: =I8/H8-1 -> 0
B11: ='Balance Sheet'!A5 -> Reserves | D11: ='Historical '!C28 -> 73041.16 | E11: ='Historical '!D28 -> 113221.83 | F11: ='Historical '!E28 -> 101860.86 | G11: ='Historical '!F28 -> 90788.32 | H11: ='Historical '!G28 -> 89922.19 | I11: ='Historical '!H28 -> 100920.21
B12: y-o-y growth | D12: 0 | E12: =E11/D11-1 -> 0.55010997 | F12: =F11/E11-1 -> -0.10034258 | G12: =G11/F11-1 -> -0.1087026 | H12: =H11/G11-1 -> -0.0095401038 | I12: =I11/H11-1 -> 0.12230596
B14: ='Balance Sheet'!A7 -> Borrowings | D14: ='Historical '!C29 -> 88501.41 | E14: ='Historical '!D29 -> 75561.35 | F14: ='Historical '!E29 -> 84893.05 | G14: ='Historical '!F29 -> 87082.12 | H14: ='Historical '!G29 -> 94801.05 | I14: ='Historical '!H29 -> 92381.68
B15: y-o-y growth | D15: 0 | E15: =E14/D14-1 -> -0.14621304 | F15: =F14/E14-1 -> 0.12349832 | G15: =G14/F14-1 -> 0.02578621 | H15: =H14/G14-1 -> 0.088639666 | I15: =I14/H14-1 -> -0.025520498
B17: ='Balance Sheet'!A8 -> Other Liabilities | D17: ='Historical '!C30 -> 52803.01 | E17: ='Historical '!D30 -> 52399.28 | F17: ='Historical '!E30 -> 56193.63 | G17: ='Historical '!F30 -> 57195.54 | H17: ='Historical '!G30 -> 58518.9 | I17: ='Historical '!H30 -> 64933.29
B18: y-o-y growth | D18: 0 | E18: =E17/D17-1 -> -0.0076459656 | F18: =F17/E17-1 -> 0.072412255 | G18: =G17/F17-1 -> 0.017829601 | H18: =H17/G17-1 -> 0.023137468 | I18: =I17/H17-1 -> 0.10961228
B20: Trade Payables | D20: ='Historical '!C31 -> 25967 | E20: ='Historical '!D31 -> 36765 | F20: ='Historical '!E31 -> 37833 | G20: ='Historical '!F31 -> 30228 | H20: ='Historical '!G31 -> 29314 | I20: ='Historical '!H31 -> 34810
B21: y-o-y growth | D21: 0 | E21: =E20/D20-1 -> 0.41583548 | F21: =F20/E20-1 -> 0.029049368 | G21: =G20/F20-1 -> -0.20101499 | H21: =H20/G20-1 -> -0.030236866 | I21: =I20/H20-1 -> 0.18748721
B23: Advance From Customers | D23: ='Historical '!C32 -> 2399 | E23: ='Historical '!D32 -> 3253 | F23: ='Historical '!E32 -> 3394 | G23: ='Historical '!F32 -> 2771 | H23: ='Historical '!G32 -> 1655 | I23: ='Historical '!H32 -> 2222
B24: y-o-y growth | D24: 0 | E24: =E23/D23-1 -> 0.35598166 | F24: =F23/E23-1 -> 0.043344605 | G24: =G23/F23-1 -> -0.18355922 | H24: =H23/G23-1 -> -0.40274269 | I24: =I23/H23-1 -> 0.34259819
B26: Fixed Assets | D26: ='Historical '!C35 -> 135775.18 | E26: ='Historical '!D35 -> 133287.83 | F26: ='Historical '!E35 -> 146621.46 | G26: ='Historical '!F35 -> 148814.38 | H26: ='Historical '!G35 -> 150914.06 | I26: ='Historical '!H35 -> 179908.13
B27: y-o-y growth | D27: 0 | E27: =E26/D26-1 -> -0.018319622 | F27: =F26/E26-1 -> 0.10003636 | G27: =G26/F26-1 -> 0.014956337 | H27: =H26/G26-1 -> 0.014109389 | I27: =I26/H26-1 -> 0.19212305
B29: Capital Work in Progress | D29: ='Historical '!C36 -> 19007.4 | E29: ='Historical '!D36 -> 22045.55 | F29: ='Historical '!E36 -> 31213.02 | G29: ='Historical '!F36 -> 34355.53 | H29: ='Historical '!G36 -> 41622.35 | I29: ='Historical '!H36 -> 28496.71
B30: y-o-y growth | D30: 0 | E30: =E29/D29-1 -> 0.15984038 | F30: =F29/E29-1 -> 0.4158422 | G30: =G29/F29-1 -> 0.10067946 | H30: =H29/G29-1 -> 0.2115182 | I30: =I29/H29-1 -> -0.31535077
B32: Investments | D32: ='Historical '!C37 -> 10681.93 | E32: ='Historical '!D37 -> 13139.85 | F32: ='Historical '!E37 -> 8410.31 | G32: ='Historical '!F37 -> 6257.57 | H32: ='Historical '!G37 -> 6194.11 | I32: ='Historical '!H37 -> 7088.85
B33: y-o-y growth | D33: 0 | E33: =E32/D32-1 -> 0.23010074 | F33: =F32/E32-1 -> -0.35993866 | G33: =G32/F32-1 -> -0.25596441 | H33: =H32/G32-1 -> -0.010141317 | I33: =I32/H32-1 -> 0.14445013
B35: Others Assets | D35: ='Historical '!C38 -> 29846.28 | E35: ='Historical '!D38 -> 36978.69 | F35: ='Historical '!E38 -> 23121.16 | G35: ='Historical '!F38 -> 15786.18 | H35: ='Historical '!G38 -> 15231.08 | I35: ='Historical '!H38 -> 18797.29
B36: y-o-y growth | D36: 0 | E36: =E35/D35-1 -> 0.23897149 | F36: =F35/E35-1 -> -0.37474367 | G36: =G35/F35-1 -> -0.317241 | H36: =H35/G35-1 -> -0.035163668 | I36: =I35/H35-1 -> 0.23414032
B38: Recievables | D38: ='Historical '!C41 -> 9539.84 | E38: ='Historical '!D41 -> 12246.43 | F38: ='Historical '!E41 -> 8257.24 | G38: ='Historical '!F41 -> 6263.53 | H38: ='Historical '!G41 -> 5260.06 | I38: ='Historical '!H41 -> 4916.89
B39: y-o-y growth | D39: 0 | E39: =E38/D38-1 -> 0.2837144 | F39: =F38/E38-1 -> -0.32574309 | G39: =G38/F38-1 -> -0.24144993 | H39: =H38/G38-1 -> -0.16020838 | I39: =I38/H38-1 -> -0.065240701
B41: Inventory | D41: ='Historical '!C42 -> 33276.38 | E41: ='Historical '!D42 -> 48824.39 | F41: ='Historical '!E42 -> 54415.33 | G41: ='Historical '!F42 -> 49157.51 | H41: ='Historical '!G42 -> 44589.94 | I41: ='Historical '!H42 -> 47249.22
B42: y-o-y growth | D42: 0 | E42: =E41/D41-1 -> 0.46723862 | F42: =F41/E41-1 -> 0.11451121 | G42: =G41/F41-1 -> -0.096623874 | H42: =H41/G41-1 -> -0.092917033 | I42: =I41/H41-1 -> 0.059638564
B44: Cash at Bank | D44: ='Historical '!C43 -> 5782.18 | E44: ='Historical '!D43 -> 15898.93 | F44: ='Historical '!E43 -> 13357.26 | G44: ='Historical '!F43 -> 8677.72 | H44: ='Historical '!G43 -> 11646.98 | I44: ='Historical '!H43 -> 10057.53
B45: y-o-y growth | D45: 0 | E45: =E44/D44-1 -> 1.7496429 | F45: =F44/E44-1 -> -0.15986422 | G45: =G44/F44-1 -> -0.35033682 | H45: =H44/G44-1 -> 0.34217052 | I45: =I44/H44-1 -> -0.13646885

Sheet Common Balance Sheet
B1: Comparative Statement
B4: Balance Sheet
B5: (In Cr)
B6: Particulars | D6: 44256 | E6: ='Profit & Loss'!G3 -> 44651 | F6: ='Profit & Loss'!H3 -> 45016 | G6: ='Profit & Loss'!I3 -> 45382 | H6: ='Profit & Loss'!J3 -> 45747 | I6: ='Profit & Loss'!K3 -> 46112 | K6: Trend Analysis
B8: ='Balance Sheet'!A4 -> Equity Share Capital | D8: ='Historical '!C27 -> 1197.61 | E8: ='Historical '!D27 -> 1221.21 | F8: ='Historical '!E27 -> 1221.24 | G8: ='Historical '!F27 -> 1247.44 | H8: ='Historical '!G27 -> 1247.44 | I8: ='Historical '!H27 -> 1247.44
B9: y-o-y growth | D9: =D8/'Historical '!C$46 -> 0.0049100651 | E9: =E8/'Historical '!D$46 -> 0.0043240662 | F9: =F8/'Historical '!E$46 -> 0.0042791102 | G9: =G8/'Historical '!F$46 -> 0.0046319438 | H9: =H8/'Historical '!G$46 -> 0.0045285937 | I9: =I8/'Historical '!H$46 -> 0.0042070101
B11: ='Balance Sheet'!A5 -> Reserves | D11: ='Historical '!C28 -> 73041.16 | E11: ='Historical '!D28 -> 113221.83 | F11: ='Historical '!E28 -> 101860.86 | G11: ='Historical '!F28 -> 90788.32 | H11: ='Historical '!G28 -> 89922.19 | I11: ='Historical '!H28 -> 100920.21
B12: y-o-y growth | D12: =D11/'Historical '!C$46 -> 0.29946047 | E12: =E11/'Historical '!D$46 -> 0.4008964 | F12: =F11/'Historical '!E$46 -> 0.35691088 | G12: =G11/'Historical '!F$46 -> 0.33711152 | H12: =H11/'Historical '!G$46 -> 0.32644541 | I12: =I11/'Historical '!H$46 -> 0.34035492
B14: ='Balance Sheet'!A7 -> Borrowings | D14: ='Historical '!C29 -> 88501.41 | E14: ='Historical '!D29 -> 75561.35 | F14: ='Historical '!E29 -> 84893.05 | G14: ='Historical '!F29 -> 87082.12 | H14: ='Historical '!G29 -> 94801.05 | I14: ='Historical '!H29 -> 92381.68
B15: y-o-y growth | D15: =D14/'Historical '!C$46 -> 0.36284574 | E15: =E14/'Historical '!D$46 -> 0.26754799 | F15: =F14/'Historical '!E$46 -> 0.29745727 | G15: =G14/'Historical '!F$46 -> 0.32334981 | H15: =H14/'Historical '!G$46 -> 0.34415719 | I15: =I14/'Historical '!H$46 -> 0.3115586
B17: ='Balance Sheet'!A8 -> Other Liabilities | D17: ='Historical '!C30 -> 52803.01 | E17: ='Historical '!D30 -> 52399.28 | F17: ='Historical '!E30 -> 56193.63 | G17: ='Historical '!F30 -> 57195.54 | H17: ='Historical '!G30 -> 58518.9 | I17: ='Historical '!H30 -> 64933.29
B18: y-o-y growth | D18: =D17/'Historical '!C$46 -> 0.21648635 | E18: =E17/'Historical '!D$46 -> 0.18553562 | F18: =F17/'Historical '!E$46 -> 0.1968972 | G18: =G17/'Historical '!F$46 -> 0.21237617 | H18: =H17/'Historical '!G$46 -> 0.21244174 | I18: =I17/'Historical '!H$46 -> 0.21898849
B20: Trade Payables | D20: ='Historical '!C31 -> 25967 | E20: ='Historical '!D31 -> 36765 | F20: ='Historical '!E31 -> 37833 | G20: ='Historical '!F31 -> 30228 | H20: ='Historical '!G31 -> 29314 | I20: ='Historical '!H31 -> 34810
B21: y-o-y growth | D21: =D20/'Historical '!C$46 -> 0.10646175 | E21: =E20/'Historical '!D$46 -> 0.13017769 | F21: =F20/'Historical '!E$46 -> 0.13256328 | G21: =G20/'Historical '!F$46 -> 0.11224139 | H21: =H20/'Historical '!G$46 -> 0.1064189 | I21: =I20/'Historical '!H$46 -> 0.11739725
B23: Advance From Customers | D23: ='Historical '!C32 -> 2399 | E23: ='Historical '!D32 -> 3253 | F23: ='Historical '!E32 -> 3394 | G23: ='Historical '!F32 -> 2771 | H23: ='Historical '!G32 -> 1655 | I23: ='Historical '!H32 -> 2222
B24: y-o-y growth | D24: =D23/'Historical '!C$46 -> 0.0098356278 | E24: =E23/'Historical '!D$46 -> 0.011518238 | F24: =F23/'Historical '!E$46 -> 0.011892257 | G24: =G23/'Historical '!F$46 -> 0.010289165 | H24: =H23/'Historical '!G$46 -> 0.0060081628 | I24: =I23/'Historical '!H$46 -> 0.0074937283
B26: Fixed Assets | D26: ='Historical '!C35 -> 135775.18 | E26: ='Historical '!D35 -> 133287.83 | F26: ='Historical '!E35 -> 146621.46 | G26: ='Historical '!F35 -> 148814.38 | H26: ='Historical '!G35 -> 150914.06 | I26: ='Historical '!H35 -> 179908.13
B27: y-o-y growth | D27: =D26/'Historical '!C$46 -> 0.55666283 | E27: =E26/'Historical '!D$46 -> 0.47194619 | F27: =F26/'Historical '!E$46 -> 0.51374782 | G27: =G26/'Historical '!F$46 -> 0.55257154 | H27: =H26/'Historical '!G$46 -> 0.5478648 | I27: =I26/'Historical '!H$46 -> 0.60674286
B29: Capital Work in Progress | D29: ='Historical '!C36 -> 19007.4 | E29: ='Historical '!D36 -> 22045.55 | F29: ='Historical '!E36 -> 31213.02 | G29: ='Historical '!F36 -> 34355.53 | H29: ='Historical '!G36 -> 41622.35 | I29: ='Historical '!H36 -> 28496.71
B30: y-o-y growth | D30: =D29/'Historical '!C$46 -> 0.077928183 | E30: =E29/'Historical '!D$46 -> 0.078058989 | F30: =F29/'Historical '!E$46 -> 0.10936749 | G30: =G29/'Historical '!F$46 -> 0.12756757 | H30: =H29/'Historical '!G$46 -> 0.15110203 | I30: =I29/'Historical '!H$46 -> 0.096105582
B32: Investments | D32: ='Historical '!C37 -> 10681.93 | E32: ='Historical '!D37 -> 13139.85 | F32: ='Historical '!E37 -> 8410.31 | G32: ='Historical '!F37 -> 6257.57 | H32: ='Historical '!G37 -> 6194.11 | I32: ='Historical '!H37 -> 7088.85
B33: y-o-y growth | D33: =D32/'Historical '!C$46 -> 0.043794701 | E33: =E32/'Historical '!D$46 -> 0.046525644 | F33: =F32/'Historical '!E$46 -> 0.029468936 | G33: =G32/'Historical '!F$46 -> 0.023235356 | H33: =H32/'Historical '!G$46 -> 0.022486539 | I33: =I32/'Historical '!H$46 -> 0.023907253
B35: Others Assets | D35: ='Historical '!C38 -> 29846.28 | E35: ='Historical '!D38 -> 36978.69 | F35: ='Historical '!E38 -> 23121.16 | G35: ='Historical '!F38 -> 15786.18 | H35: ='Historical '!G38 -> 15231.08 | I35: ='Historical '!H38 -> 18797.29
B36: y-o-y growth | D36: =D35/'Historical '!C$46 -> 0.12236636 | E36: =E35/'Historical '!D$46 -> 0.13093432 | F36: =F35/'Historical '!E$46 -> 0.081014372 | G36: =G35/'Historical '!F$46 -> 0.058616606 | H36: =H35/'Historical '!G$46 -> 0.05529354 | I36: =I35/'Historical '!H$46 -> 0.063394142
B38: Recievables | D38: ='Historical '!C41 -> 9539.84 | E38: ='Historical '!D41 -> 12246.43 | F38: ='Historical '!E41 -> 8257.24 | G38: ='Historical '!F41 -> 6263.53 | H38: ='Historical '!G41 -> 5260.06 | I38: ='Historical '!H41 -> 4916.89
B39: y-o-y growth | D39: =D38/'Historical '!C$46 -> 0.039112261 | E39: =E38/'Historical '!D$46 -> 0.043362218 | F39: =F38/'Historical '!E$46 -> 0.028932593 | G39: =G38/'Historical '!F$46 -> 0.023257487 | H39: =H38/'Historical '!G$46 -> 0.019095648 | I39: =I38/'Historical '!H$46 -> 0.016582285
B41: Inventory | D41: ='Historical '!C42 -> 33276.38 | E41: ='Historical '!D42 -> 48824.39 | F41: ='Historical '!E42 -> 54415.33 | G41: ='Historical '!F42 -> 49157.51 | H41: ='Historical '!G42 -> 44589.94 | I41: ='Historical '!H42 -> 47249.22
B42: y-o-y growth | D42: =D41/'Historical '!C$46 -> 0.13642938 | E42: =E41/'Historical '!D$46 -> 0.17287763 | F42: =F41/'Historical '!E$46 -> 0.1906662 | G42: =G41/'Historical '!F$46 -> 0.18252968 | H42: =H41/'Historical '!G$46 -> 0.1618753 | I42: =I41/'Historical '!H$46 -> 0.1593487
B44: Cash at Bank | D44: ='Historical '!C43 -> 5782.18 | E44: ='Historical '!D43 -> 15898.93 | F44: ='Historical '!E43 -> 13357.26 | G44: ='Historical '!F43 -> 8677.72 | H44: ='Historical '!G43 -> 11646.98 | I44: ='Historical '!H43 -> 10057.53
B45: y-o-y growth | D45: =D44/'Historical '!C$46 -> 0.023706282 | E45: =E44/'Historical '!D$46 -> 0.056295007 | F45: =F44/'Historical '!E$46 -> 0.046802584 | G45: =G44/'Historical '!F$46 -> 0.032221759 | H45: =H44/'Historical '!G$46 -> 0.042282146 | I45: =I44/'Historical '!H$46 -> 0.033919171

Sheet Common Income Statement
B1: Comparative Statement
B4: Income Statement
B5: (In Cr)
B6: Particulars | D6: 44256 | E6: ='Profit & Loss'!G3 -> 44651 | F6: ='Profit & Loss'!H3 -> 45016 | G6: ='Profit & Loss'!I3 -> 45382 | H6: ='Profit & Loss'!J3 -> 45747 | I6: ='Profit & Loss'!K3 -> 46112 | K6: Trend Analysis
B8: ='Profit & Loss'!A4 -> Sales | D8: ='Historical '!C7 -> 156477.4 | E8: ='Historical '!D7 -> 243959.17 | F8: ='Historical '!E7 -> 243352.69 | G8: ='Historical '!F7 -> 229170.78 | H8: ='Historical '!G7 -> 218542.51 | I8: ='Historical '!H7 -> 232139.94
B9: y-o-y growth | D9: =D8/D8 -> 1 | E9: =E8/E8 -> 1 | F9: =F8/F8 -> 1 | G9: =G8/G8 -> 1 | H9: =H8/H8 -> 1 | I9: =I8/I8 -> 1
B11: Cost of Goods Sold | D11: ='Historical '!C8 -> 102979.74 | E11: ='Historical '!D8 -> 143605.19 | F11: ='Historical '!E8 -> 178329.36 | G11: ='Historical '!F8 -> 183154.84 | H11: ='Historical '!G8 -> 171714.99 | I11: ='Historical '!H8 -> 171435.78
B12: y-o-y growth | D12: =D11/D$8 -> 0.65811255 | E12: =E11/E$8 -> 0.58864436 | F12: =F11/F$8 -> 0.73280209 | G12: =G11/G$8 -> 0.79920677 | H12: =H11/H$8 -> 0.78572809 | I12: =I11/I$8 -> 0.73850187
B14: Gross Profit | D14: ='Historical '!C9 -> 53497.66 | E14: ='Historical '!D9 -> 100353.98 | F14: ='Historical '!E9 -> 65023.33 | G14: ='Historical '!F9 -> 46015.94 | H14: ='Historical '!G9 -> 46827.52 | I14: ='Historical '!H9 -> 60704.16
B15: y-o-y growth | D15: =D14/D$8 -> 0.34188745 | E15: =E14/E$8 -> 0.41135564 | F15: =F14/F$8 -> 0.26719791 | G15: =G14/G$8 -> 0.20079323 | H15: =H14/H$8 -> 0.21427191 | I15: =I14/I$8 -> 0.26149813
B17: Selling & General Expenses | D17: ='Historical '!C10 -> 22993.4 | E17: ='Historical '!D10 -> 36864.03 | F17: ='Historical '!E10 -> 32723.17 | G17: ='Historical '!F10 -> 23768.02 | H17: ='Historical '!G10 -> 21529.07 | I17: ='Historical '!H10 -> 26351.72
B18: y-o-y growth | D18: =D17/D$8 -> 0.1469439 | E18: =E17/E$8 -> 0.15110738 | F18: =F17/F$8 -> 0.13446808 | G18: =G17/G$8 -> 0.10371313 | H18: =H17/H$8 -> 0.098512047 | I18: =I17/I$8 -> 0.11351653
B20: EBITDA | D20: ='Historical '!C11 -> 30504.26 | E20: ='Historical '!D11 -> 63489.95 | F20: ='Historical '!E11 -> 32300.16 | G20: ='Historical '!F11 -> 22247.92 | H20: ='Historical '!G11 -> 25298.45 | I20: ='Historical '!H11 -> 34352.44
B21: y-o-y growth | D21: =D20/D$8 -> 0.19494355 | E21: =E20/E$8 -> 0.26024826 | F21: =F20/F$8 -> 0.13272983 | G21: =G20/G$8 -> 0.09708009 | H21: =H20/H$8 -> 0.11575986 | I21: =I20/I$8 -> 0.1479816
B23: Interest | D23: ='Historical '!C12 -> 7606.71 | E23: ='Profit & Loss'!G9 -> 5462.2 | F23: ='Profit & Loss'!H9 -> 6298.7 | G23: ='Profit & Loss'!I9 -> 7507.57 | H23: ='Profit & Loss'!J9 -> 7340.95 | I23: ='Profit & Loss'!K9 -> 7167.06
B24: y-o-y growth | D24: =D23/D$8 -> 0.048612196 | E24: =E23/E$8 -> 0.022389812 | F24: =F23/F$8 -> 0.02588301 | G24: =G23/G$8 -> 0.032759717 | H24: =H23/H$8 -> 0.03359049 | I24: =I23/I$8 -> 0.030873877
B26: Depreciation | D26: ='Historical '!C13 -> 9233.64 | E26: ='Historical '!D13 -> 9100.87 | F26: ='Historical '!E13 -> 9335.2 | G26: ='Historical '!F13 -> 9882.16 | H26: ='Historical '!G13 -> 10421.33 | I26: ='Historical '!H13 -> 11954.51
B27: y-o-y growth | D27: =D26/D$8 -> 0.059009416 | E27: =E26/E$8 -> 0.03730489 | F27: =F26/F$8 -> 0.038360784 | G27: =G26/G$8 -> 0.043121379 | H27: =H26/H$8 -> 0.047685597 | I27: =I26/I$8 -> 0.051496998
B29: Other Income | D29: ='Historical '!C14 -> 179.78 | E29: ='Historical '!D14 -> 1299.99 | F29: ='Historical '!E14 -> 1568.86 | G29: ='Historical '!F14 -> -6005.23 | H29: ='Historical '!G14 -> 876.7 | I29: ='Historical '!H14 -> 737.82
B30: y-o-y growth | D30: =D29/D$8 -> 0.0011489199 | E30: =E29/E$8 -> 0.0053287196 | F30: =F29/F$8 -> 0.006446857 | G30: =G29/G$8 -> -0.02620417 | H30: =H29/H$8 -> 0.0040115765 | I30: =I29/I$8 -> 0.0031783415
B32: Earnings Before Tax | D32: ='Historical '!C15 -> 13843.69 | E32: ='Historical '!D15 -> 50226.87 | F32: ='Historical '!E15 -> 18235.12 | G32: ='Historical '!F15 -> -1147.04 | H32: ='Historical '!G15 -> 8412.87 | I32: ='Historical '!H15 -> 15968.69
B33: y-o-y growth | D33: =D32/D$8 -> 0.088470859 | E33: =E32/E$8 -> 0.20588228 | F33: =F32/F$8 -> 0.074932889 | G33: =G32/G$8 -> -0.0050051756 | H33: =H32/H$8 -> 0.038495348 | I33: =I32/I$8 -> 0.068789067
B35: Tax | D35: ='Historical '!C16 -> 5653.9 | E35: ='Historical '!D16 -> 8477.55 | F35: ='Historical '!E16 -> 10159.77 | G35: ='Historical '!F16 -> 3762.57 | H35: ='Historical '!G16 -> 5239.09 | I35: ='Historical '!H16 -> 5082.87
B36: y-o-y growth | D36: =D35/D$8 -> 0.036132374 | E36: =E35/E$8 -> 0.034749872 | F36: =F35/F$8 -> 0.041749158 | G36: =G35/G$8 -> 0.016418193 | H36: =H35/H$8 -> 0.023972865 | I36: =I35/I$8 -> 0.021895715
B38: Net Profit | D38: ='Historical '!C17 -> 8189.79 | E38: ='Historical '!D17 -> 41749.32 | F38: ='Historical '!E17 -> 8075.35 | G38: ='Historical '!F17 -> -4909.61 | H38: ='Historical '!G17 -> 3173.78 | I38: ='Historical '!H17 -> 10885.82
B39: y-o-y growth | D39: =D38/D$8 -> 0.052338485 | E39: =E38/E$8 -> 0.17113241 | F39: =F38/F$8 -> 0.03318373 | G39: =G38/G$8 -> -0.021423368 | H39: =H38/H$8 -> 0.014522484 | I39: =I38/I$8 -> 0.046893352

Sheet Altman's scroe
B1: Altman's Z Score
B4: Financial Summary
B29: Workinng Capital/Total Assets
E30: ='[1]Reinvestment rate'!F34 -> 44986 | F30: ='[1]Reinvestment rate'!G34 -> 45352 | G30: ='[1]Reinvestment rate'!H34 -> 45717 | H30: ='[1]Reinvestment rate'!I34 -> 46082
B31: Working Capital | E31: ='Historical '!E60 -> -3706 | F31: ='Historical '!F60 -> 3384 | G31: ='Historical '!G60 -> 2207 | H31: ='Historical '!H60 -> 5442
B32: Total Assets | E32: ='Historical '!E46 -> 285395.78 | F32: ='Historical '!F46 -> 269312.42 | G32: ='Historical '!G46 -> 275458.58 | H32: ='Historical '!H46 -> 296514.62
B33: Working Capital/Total Assets (A) | E33: =E31/E32 -> -0.012985476 | F33: =F31/F32 -> 0.012565332 | G33: =G31/G32 -> 0.0080120939 | H33: =H31/H32 -> 0.018353227
B35: Retained Earnings /Total Assets
E36: =E30 -> 44986 | F36: =F30 -> 45352 | G36: =G30 -> 45717 | H36: =H30 -> 46082
B37: Retained Earnings | E37: ='Historical '!E28 -> 101860.86 | F37: ='Historical '!F28 -> 90788.32 | G37: ='Historical '!G28 -> 89922.19 | H37: ='Historical '!H28 -> 100920.21
B38: =B32 -> Total Assets | E38: =E32 -> 285395.78 | F38: =F32 -> 269312.42 | G38: =G32 -> 275458.58 | H38: =H32 -> 296514.62
B39: Retained Earnings/Total Assets (B) | E39: =E37/E38 -> 0.35691088 | F39: =F37/F38 -> 0.33711152 | G39: =G37/G38 -> 0.32644541 | H39: =H37/H38 -> 0.34035492
B41: EBIT/Total Assets
E42: 44986 | F42: 45352 | G42: 45717 | H42: 46082
B43: EBIT | E43: ='Historical '!C15+'Historical '!C12 -> 21450.4 | F43: ='Historical '!D15+'Historical '!D12 -> 55689.07 | G43: ='Historical '!E15+'Historical '!E12 -> 24533.82 | H43: ='Historical '!F15+'Historical '!F12 -> 6360.53
B44: =B38 -> Total Assets | E44: =E38 -> 285395.78 | F44: =F38 -> 269312.42 | G44: =G38 -> 275458.58 | H44: =H38 -> 296514.62
B45: EBIT/Total Assets (C) | E45: =E43/E44 -> 0.075160186 | F45: =F43/F44 -> 0.20678241 | G45: =G43/G44 -> 0.089065369 | H45: =H43/H44 -> 0.021450983
B47: Market Cap/Long Term Liabilities
E48: 44986 | F48: 45352 | G48: 45717 | H48: 46082
B49: Market Cap | E49: 173200 | F49: 174000 | G49: 210700 | H49: 233842
B50: Long Term Liabilities | E50: ='Balance Sheet'!H10 -> 51446 | F50: ='Balance Sheet'!I10 -> 51577 | G50: ='Balance Sheet'!J10 -> 68552 | H50: ='Balance Sheet'!K10 -> 63754
B51: Market Cap/Long Term Liabilities (D) | E51: =E49/E50 -> 3.3666369 | F51: =F49/F50 -> 3.3735968 | G51: =G49/G50 -> 3.0735792 | H51: =H49/H50 -> 3.6678797
B53: Sales/Total Assets
E54: 44986 | F54: 45352 | G54: 45717 | H54: 46082
B55: Sales | E55: ='Historical '!E7 -> 243352.69 | F55: ='Historical '!F7 -> 229170.78 | G55: ='Historical '!G7 -> 218542.51 | H55: ='Historical '!H7 -> 232139.94
B56: Total Assets | E56: =E38 -> 285395.78 | F56: =F38 -> 269312.42 | G56: =G38 -> 275458.58 | H56: =H38 -> 296514.62
B57: Return on Assets (E) | E57: =E55/E56 -> 0.85268496 | F57: =F55/F56 -> 0.85094768 | G57: =G55/G56 -> 0.79337703 | H57: =H55/H56 -> 0.78289543
B59: Altman's Score
E60: =E30 -> 44986 | F60: =F30 -> 45352 | G60: =G30 -> 45717 | H60: =H30 -> 46082
B61: Final Score | E61: =(E33*1.2)+(E39*1.5)+(E45*3.3)+(E51*0.9)+(E57*1.7) -> 5.24735 | F61: =(F33*1.2)+(F39*1.5)+(F45*3.3)+(F51*0.9)+(F57*1.7) -> 5.6859758 | G61: =(G33*1.2)+(G39*1.5)+(G45*3.3)+(G51*0.9)+(G57*1.7) -> 4.9081606 | H61: =(H33*1.2)+(H39*1.5)+(H45*3.3)+(H51*0.9)+(H57*1.7) -> 5.2353584
B62: Financial Stability | E62: =IF(E61<1.81," Distressed",IF(E61>3,"Strong","Grey Zone")) -> Strong | F62: =IF(F61<1.81," Distressed",IF(F61>3,"Strong","Grey Zone")) -> Strong | G62: =IF(G61<1.81," Distressed",IF(G61>3,"Strong","Grey Zone")) -> Strong | H62: =IF(H61<1.81," Distressed",IF(H61>3,"Strong","Grey Zone")) -> Strong

Sheet Dupont Analysis
B1: Dupont Analysis
B4: (TATA Steel BSE Code: 500470)
B5: Current Price: INR 187
B7: 52 Week (High: 224.40 & Low: 152.55)
B9: Financial Summary
B34: Return on Equity (ROE)
E35: ='[1]Reinvestment rate'!F34 -> 44986 | F35: ='[1]Reinvestment rate'!G34 -> 45352 | G35: ='[1]Reinvestment rate'!H34 -> 45717 | H35: ='[1]Reinvestment rate'!I34 -> 46082
B36: Net Profit | E36: ='Historical '!E17 -> 8075.35 | F36: ='Historical '!F17 -> -4909.61 | G36: ='Historical '!G17 -> 3173.78 | H36: ='Historical '!H17 -> 10885.82
B37: Average Shareholder Equity | E37: ='Balance Sheet'!H6 -> 108762.57 | F37: ='Balance Sheet'!I6 -> 97558.93 | G37: ='Balance Sheet'!J6 -> 91602.695 | H37: ='Balance Sheet'!K6 -> 96668.64
B38: Return on Equity | E38: =E36/E37 -> 0.07424751 | F38: =F36/F37 -> -0.050324558 | G38: =G36/G37 -> 0.034647234 | H38: =H36/H37 -> 0.11260963
B40: ROE-Dupont Equation
E41: =E35 -> 44986 | F41: =F35 -> 45352 | G41: =G35 -> 45717 | H41: =H35 -> 46082
B42: =B36 -> Net Profit | E42: =E36 -> 8075.35 | F42: =F36 -> -4909.61 | G42: =G36 -> 3173.78 | H42: =H36 -> 10885.82
B43: Revenue | E43: ='Historical '!E7 -> 243352.69 | F43: ='Historical '!F7 -> 229170.78 | G43: ='Historical '!G7 -> 218542.51 | H43: ='Historical '!H7 -> 232139.94
B44: Net Profit Margin (A) | E44: =E42/E43 -> 0.03318373 | F44: =F42/F43 -> -0.021423368 | G44: =G42/G43 -> 0.014522484 | H44: =H42/H43 -> 0.046893352
E46: 44986 | F46: 45352 | G46: 45717 | H46: 46082
B47: Revenue | E47: =E43 -> 243352.69 | F47: =F43 -> 229170.78 | G47: =G43 -> 218542.51 | H47: =H43 -> 232139.94
B48: Average Total Assets | E48: ='Balance Sheet'!H16 -> 390458.44 | F48: ='Balance Sheet'!I16 -> 366872.07 | G48: ='Balance Sheet'!J16 -> 350692 | H48: ='Balance Sheet'!K16 -> 364861.09
B49: Asset Turnover Ratio (B) | E49: =E47/E48 -> 0.62324864 | F49: =F47/F48 -> 0.6246613 | G49: =G47/G48 -> 0.62317507 | H49: =H47/H48 -> 0.63624196
E51: 44986 | F51: 45352 | G51: 45717 | H51: 46082
B52: Average Total Assets | E52: =E48 -> 390458.44 | F52: =F48 -> 366872.07 | G52: =G48 -> 350692 | H52: =H48 -> 364861.09
B53: Average Shareholder Equity | E53: =E37 -> 108762.57 | F53: =F37 -> 97558.93 | G53: =G37 -> 91602.695 | H53: =H37 -> 96668.64
B54: Equity Mulitplier (C) | E54: =E52/E53 -> 3.5900075 | F54: =F52/F53 -> 3.7605175 | G54: =G52/G53 -> 3.8284026 | H54: =H52/H53 -> 3.7743481
B56: Return on Equity (A*B*C) | E56: =E44*E49*E54 -> 0.07424751 | F56: =F44*F49*F54 -> -0.050324558 | G56: =G44*G49*G54 -> 0.034647234 | H56: =H44*H49*H54 -> 0.11260963
B58: Return on Asset
E59: =E35 -> 44986 | F59: =F35 -> 45352 | G59: =G35 -> 45717 | H59: =H35 -> 46082
B60: Net Profit | E60: =E42 -> 8075.35 | F60: =F42 -> -4909.61 | G60: =G42 -> 3173.78 | H60: =H42 -> 10885.82
B61: =B48 -> Average Total Assets | E61: =E52 -> 390458.44 | F61: =F52 -> 366872.07 | G61: =G52 -> 350692 | H61: =H52 -> 364861.09
B62: Return on Asset | E62: =E60/E61 -> 0.020681715 | F62: =F60/F61 -> -0.013382349 | G62: =G60/G61 -> 0.0090500496 | H62: =H60/H61 -> 0.029835519
B64: ROA - Dupont Equation
E65: =E59 -> 44986 | F65: =F59 -> 45352 | G65: =G59 -> 45717 | H65: =H59 -> 46082
B66: =B60 -> Net Profit | E66: =E42 -> 8075.35 | F66: =F42 -> -4909.61 | G66: =G42 -> 3173.78 | H66: =H42 -> 10885.82
B67: Revenue | E67: =E43 -> 243352.69 | F67: =F43 -> 229170.78 | G67: =G43 -> 218542.51 | H67: =H43 -> 232139.94
B68: Net Profit Margin (A) | E68: =E66/E67 -> 0.03318373 | F68: =F66/F67 -> -0.021423368 | G68: =G66/G67 -> 0.014522484 | H68: =H66/H67 -> 0.046893352
E70: =E46 -> 44986 | F70: =F46 -> 45352 | G70: =G46 -> 45717 | H70: =H46 -> 46082
B71: Revenue | E71: =E67 -> 243352.69 | F71: =F67 -> 229170.78 | G71: =G67 -> 218542.51 | H71: =H67 -> 232139.94
B72: Average Total Assets | E72: =E52 -> 390458.44 | F72: =F52 -> 366872.07 | G72: =G52 -> 350692 | H72: =H52 -> 364861.09
B73: Asset Turnover Ratio (B) | E73: =E71/E72 -> 0.62324864 | F73: =F71/F72 -> 0.6246613 | G73: =G71/G72 -> 0.62317507 | H73: =H71/H72 -> 0.63624196
B75: Return on Asset (A*B) | E75: =E68*E73 -> 0.020681715 | F75: =F68*F73 -> -0.013382349 | G75: =G68*G73 -> 0.0090500496 | H75: =H68*H73 -> 0.029835519

Sheet Assumption and Drivers
A1: # | B1: Operational Driver
B3: Year | D3: Steel Sales Volume (Mnt) | E3: Crude Steel Production (Mnt) | F3: Installed Capacity (Mnt) | G3: Revenue (In Cr)
B4: 2025-26 | D4: 31.97 | E4: 31.67 | F4: 22.47 | G4: 232140
B5: 2024-25 | D5: 30.96 | E5: 30.92 | F5: 20.72 | G5: =G4-13597 -> 218543
B6: 2023-24 | D6: 29.39 | E6: 29.94 | F6: 20.6 | G6: ='Profit & Loss'!I4 -> 229170.78
B7: 2022-23 | D7: 28.79 | E7: 30.65 | F7: 20.3 | G7: ='Profit & Loss'!I5 -> 206922.86
B9: Historical growth | D9: 2025-26 | E9: 2024-25 | F9: 2023-24
B10: Steel Sales Volume (Mnt) | D10: =D4/D5-1 -> 0.032622739 | E10: =D5/D6-1 -> 0.05341953 | F10: =D6/D7-1 -> 0.02084057
B11: Crude Steel Production (Mnt) | D11: =E4/E5-1 -> 0.024256145 | E11: =E5/E6-1 -> 0.032732131 | F11: =E6/E7-1 -> -0.023164763
B12: Installed Capacity (Mnt) | D12: =F4/F5-1 -> 0.084459459 | E12: =F5/F6-1 -> 0.0058252427 | F12: =F6/F7-1 -> 0.014778325
B14: Average Selling Price (ASP) | D14: Deliveries (Mnt) | E14: Revenue (Rs Cr) | F14: ASP(Rs/Tonne)
B15: 2025-26 | D15: 31.97 | E15: 232140 | F15: =E15/D15*1 -> 7261.1824
B16: 2024-25 | D16: 30.96 | E16: 218543 | F16: =E16/D16*1 -> 7058.8824
B17: 2023-24 | D17: 29.39 | E17: 229170.78 | F17: =E17/D17*1 -> 7797.5767
B18: 2022-23 | D18: 28.79 | E18: 206922.86 | F18: =E18/D18*1 -> 7187.3171
B20: Historical Drivers | D20: 2023A | E20: 2024A | F20: 2025A | G20: 2026A | H20: 2027F | I20: 2028F | J20: 2029F | K20: 2030F | L20: 2031F
B21: Sales Volume | D21: =D7 -> 28.79 | E21: =D6 -> 29.39 | F21: =D5 -> 30.96 | G21: =D4 -> 31.97 | H21: =G21*(1+H22) -> 33.40865 | I21: =H21*(1+I22) -> 35.1459 | J21: =I21*(1+J22) -> 36.727465 | K21: =J21*(1+K22) -> 38.196564 | L21: =K21*(1+L22) -> 39.724426
B22: Volume Growth | D22: 0 | E22: =E21/D21-1 -> 0.02084057 | F22: =F21/E21-1 -> 0.05341953 | G22: =G21/F21-1 -> 0.032622739 | H22: =Inputs!D11 -> 0.045 | I22: =Inputs!E11 -> 0.052 | J22: =Inputs!F11 -> 0.045 | K22: =Inputs!G11 -> 0.04 | L22: =Inputs!H11 -> 0.04
B23: Average Selling Price | D23: =F18 -> 7187.3171 | E23: =F17 -> 7797.5767 | F23: =F16 -> 7058.8824 | G23: =F15 -> 7261.1824 | H23: =G23*(1+H24) -> 7370.1001 | I23: =H23*(1+I24) -> 7443.8011 | J23: =I23*(1+J24) -> 7533.1267 | K23: =J23*(1+K24) -> 7608.458 | L23: =K23*(1+L24) -> 7707.3679
